<?xml version="1.0"?>
<robot xmlns:xacro="http://www.ros.org/wiki/xacro" name="telega">

  <!-- ==================== Properties ==================== -->
  <!-- Размеры корпуса робота (в метрах) -->
  <xacro:property name="base_length" value="0.24"/>       <!-- Длина корпуса по оси X (от переднего до заднего края), м -->
  <xacro:property name="base_width" value="0.17"/>        <!-- Ширина корпуса по оси Y (от левого до правого борта), м -->
  <xacro:property name="base_height" value="0.11"/>       <!-- Высота корпуса по оси Z (от верха до низа), м -->

  <!-- Параметры гусеницы (в метрах) -->
  <xacro:property name="track_radius" value="0.0225"/>     <!-- Радиус катков и ведущего колеса, м -->
  <xacro:property name="track_width" value="0.044"/>     <!-- Ширина гусеничной ленты, м -->
  <xacro:property name="track_length" value="0.21"/>      <!-- Длина гусеницы (зона контакта с землёй), м -->

  <!-- Массы компонентов (в кг) -->
  <xacro:property name="base_mass" value="1.067"/>         <!-- Масса корпуса, кг -->
  <xacro:property name="track_mass" value="0.030"/>        <!-- Масса одной гусеницы (лента), кг -->
  <xacro:property name="roller_mass" value="0.012"/>       <!-- Масса одного катка, кг -->

  <!-- Расстояние от центра катков до низа корпуса, м -->
  <xacro:property name="roller_to_base_gap" value="0.014"/> 
  <!-- ==================== Macros ==================== -->
  <!-- Макрос: отдельный каток (визуал + коллизия + инерция) -->
  <xacro:macro name="roller_link" params="name">
    <link name="${name}">
      <visual>
        <origin rpy="1.57075 0 0" xyz="0 0 0"/>       <!-- Поворот на 90° вокруг X, чтобы цилиндр лежал горизонтально -->
        <geometry>
          <cylinder length="${track_width}" radius="${track_radius}"/>
        </geometry>
        <material name="dark_gray"/>
      </visual>
      <collision>
        <origin rpy="1.57075 0 0" xyz="0 0 0"/>
        <geometry>
          <cylinder length="${track_width}" radius="${track_radius}"/>
        </geometry>
      </collision>
      <inertial>
        <mass value="${roller_mass}"/>                  <!-- Масса одного катка -->
        <!-- Моменты инерции катка (упрощённо) -->
        <inertia ixx="0.0005" ixy="0.0" ixz="0.0" iyy="0.0005" iyz="0.0" izz="0.0005"/>
      </inertial>
    </link>
  </xacro:macro>

  <!-- Макрос: сустав для катка (непрерывное вращение) -->
  <xacro:macro name="roller_joint" params="name parent x y z">
    <joint name="${name}_joint" type="continuous">    <!-- continuous = каток может вращаться бесконечно -->
      <parent link="${parent}"/>
      <child link="${name}"/>
      <origin rpy="0 0 0" xyz="${x} ${y} ${z}"/>     <!-- Позиция катка относительно родительского link -->
      <axis xyz="0 1 0"/>                              <!-- Ось вращения — по оси Y -->
    </joint>
  </xacro:macro>

  <!-- Макрос: полная сборка гусеницы (левая или правая) -->
  <xacro:macro name="track_assembly" params="side y_offset">
    <!-- side   = "left" или "right" (какая гусеница) -->
    <!-- y_offset = смещение по оси Y (расстояние от центра корпуса до центра гусеницы) -->

    <!-- Гусеничная лента (визуальный прямоугольник, имитирует резиновое полотно) -->
    <link name="${side}_track">
      <visual>
        <origin xyz="0 0 0" rpy="0 0 0"/>
        <geometry>
          <box size="${track_length} ${track_width} ${track_radius * 2 + 0.01}"/>  <!-- длина × ширина × высота -->
        </geometry>
        <material name="dark_gray"/>
      </visual>
      <collision>
        <origin xyz="0 0 0" rpy="0 0 0"/>
        <geometry>
          <box size="${track_length} ${track_width} ${track_radius * 2 + 0.01}"/>
        </geometry>
      </collision>
      <inertial>
        <mass value="${track_mass}"/>                   <!-- Масса гусеничной ленты -->
        <inertia ixx="0.01" ixy="0.0" ixz="0.0" iyy="0.01" iyz="0.0" izz="0.01"/>
      </inertial>
    </link>

    <!-- Фиксированный сустав: приклеивает гусеничную ленту к корпусу -->
    <joint name="${side}_track_joint" type="fixed">
      <parent link="base_link"/>
      <child link="${side}_track"/>
      <origin xyz="0 ${y_offset} ${-base_height/2 - roller_to_base_gap}" rpy="0 0 0"/>  <!-- Гусеничная лента на уровне центров катков -->
    </joint>

    <!-- ===== Колёса и катки гусеницы ===== -->

    <!-- Ведущее колесо (заднее) — крутит гусеницу -->
    <xacro:roller_link name="${side}_drive_wheel"/>
    <xacro:roller_joint name="${side}_drive_wheel" parent="base_link"
                        x="-0.095" y="${y_offset}" z="${-base_height/2 - roller_to_base_gap}"/>

    <!-- Поддерживающий каток #1 (передний) -->
    <xacro:roller_link name="${side}_support_roller_1"/>
    <xacro:roller_joint name="${side}_support_roller_1" parent="base_link"
                        x="0.1" y="${y_offset}" z="${-base_height/2 - roller_to_base_gap}"/>

    <!-- Поддерживающий каток #2 (центральный) -->
    <xacro:roller_link name="${side}_support_roller_2"/>
    <xacro:roller_joint name="${side}_support_roller_2" parent="base_link"
                        x="0.04" y="${y_offset}" z="${-base_height/2 - roller_to_base_gap}"/>

    <!-- Поддерживающий каток #3 (между центром и ведущим) -->
    <xacro:roller_link name="${side}_support_roller_3"/>
    <xacro:roller_joint name="${side}_support_roller_3" parent="base_link"
                        x="-0.035" y="${y_offset}" z="${-base_height/2 - roller_to_base_gap}"/>
  </xacro:macro>

  <!-- ==================== Materials ==================== -->
  <!-- Цвета для визуализации в RViz (R, G, B, Alpha — от 0.0 до 1.0) -->
  <material name="blue">
    <color rgba="0.2 0.4 0.8 1.0"/>                    <!-- Синий цвет для корпуса -->
  </material>
  <material name="dark_gray">
    <color rgba="0.3 0.3 0.3 1.0"/>                    <!-- Тёмно-серый для гусениц и катков -->
  </material>

  <!-- ==================== Base Link ==================== -->
  <!-- Основной корпус робота (прямоугольный параллелепипед) -->
  <link name="base_link">
    <visual>
      <geometry>
        <box size="${base_length} ${base_width} ${base_height}"/>  <!-- Длина × Ширина × Высота -->
      </geometry>
      <material name="blue"/>
    </visual>
    <collision>
      <geometry>
        <box size="${base_length} ${base_width} ${base_height}"/>  <!-- Границы для обнаружения столкновений -->
      </geometry>
    </collision>
    <inertial>
      <mass value="${base_mass}"/>                       <!-- Масса корпуса, кг -->
      <!-- Моменты инерции корпуса (упрощённо, для прямоугольника) -->
      <inertia ixx="0.05" ixy="0.0" ixz="0.0" iyy="0.05" iyz="0.0" izz="0.05"/>
    </inertial>
  </link>

  <!-- ==================== Tracks ==================== -->
  <!-- Установка двух гусениц: левая и правая -->
  <!-- Левая гусеница: смещена вправо от центра (base_width/2) на половину ширины гусеницы -->
  <xacro:track_assembly side="left" y_offset="${base_width/2 + track_width/2}"/>

  <!-- Правая гусеница: смещена влево от центра (-base_width/2) на половину ширины гусеницы -->
  <xacro:track_assembly side="right" y_offset="${-base_width/2 - track_width/2}"/>

</robot>
