<?xml version="1.0"?>
<robot name="telega">
  <link name="base_link">
    <visual>
      <geometry>
        <box size="0.6 0.3 0.2"/>
      </geometry>
    </visual>
  </link>

  <link name="left_back_wheel">
    <visual>
      <origin rpy="1.57075 0 0" xyz="0 0 0"/>
      <geometry>
        <cylinder length="0.035" radius="0.035"/>
      </geometry>
    </visual>
  </link>

  <joint name="left_back_wheel_joint" type="continuous">
    <parent link="base_link"/>
    <child link="left_back_wheel"/>
    <origin rpy="0 0 0" xyz="-0.133333333333 0 -0.085"/>
  </joint>
</robot>